<robot
  name="SCARA">
  <link
    name="base_link">
    <inertial>
      <origin
        xyz="-0.0396291619870885 -0.00871019094472842 0.100556721714378"
        rpy="0 0 0" />
      <mass
        value="2.52493509218331" />
      <inertia
        ixx="0.0219251161729945"
        ixy="5.41391490870446E-05"
        ixz="0.00187547372649678"
        iyy="0.0276170392981587"
        iyz="-4.46426244526787E-05"
        izz="0.0122037548285845" />
    </inertial>
    <visual>
      <origin
        xyz="0 0 0"
        rpy="0 0 0" />
      <geometry>
        <mesh
          filename="package://SCARA/meshes/base_link.STL" />
      </geometry>
      <material
        name="">
        <color
          rgba="0.5 0.5 0.5 1" />
      </material>
    </visual>
    <collision>
      <origin
        xyz="0 0 0"
        rpy="0 0 0" />
      <geometry>
        <mesh
          filename="package://SCARA/meshes/base_link.STL" />
      </geometry>
    </collision>
  </link>
  <link
    name="l1">
    <inertial>
      <origin
        xyz="0.0993001849908689 8.40831282055473E-05 0.0403572026071247"
        rpy="0 0 0" />
      <mass
        value="4.50906447640433" />
      <inertia
        ixx="0.108378529375537"
        ixy="0.00114604209144417"
        ixz="-0.0751796039483732"
        iyy="0.260865329677849"
        iyz="0.000428646422178779"
        izz="0.163136377396791" />
    </inertial>
    <visual>
      <origin
        xyz="0 0 0"
        rpy="0 0 0" />
      <geometry>
        <mesh
          filename="package://SCARA/meshes/l1.STL" />
      </geometry>
      <material
        name="">
        <color
          rgba="0.9 0.9 1 1" />
      </material>
    </visual>
    <collision>
      <origin
        xyz="0 0 0"
        rpy="0 0 0" />
      <geometry>
        <mesh
          filename="package://SCARA/meshes/l1.STL" />
      </geometry>
    </collision>
  </link>
  <joint
    name="j1"
    type="continuous">
    <origin
      xyz="0.013604 -0.0089828 0.1609"
      rpy="0 0 0.015307" />
    <parent
      link="base_link" />
    <child
      link="l1" />
    <axis
      xyz="0 0 1" />
    <limit
      lower="-1.57"
      upper="1.57"
      effort="100"
      velocity="0.1" />
    <dynamics
      damping="0.01"
      friction="0.1" />
    <safety_controller
      soft_upper_limit="1.57"
      soft_lower_limit="-1.57"
      k_position="50"
      k_velocity="0.1" />
  </joint>
  <link
    name="l2">
    <inertial>
      <origin
        xyz="0.9 0.9 0.9"
        rpy="0 0 0" />
      <mass
        value="1.85927049885449" />
      <inertia
        ixx="0.0258798098082923"
        ixy="-1.38278900689575E-05"
        ixz="0.00996151935474917"
        iyy="0.0376910175827527"
        iyz="3.98874127723958E-05"
        izz="0.0159200656823878" />
    </inertial>
    <visual>
      <origin
        xyz="0 0 0"
        rpy="0 0 0" />
      <geometry>
        <mesh
          filename="package://SCARA/meshes/l2.STL" />
      </geometry>
      <material
        name="">
        <color
          rgba="0.666666666666667 0.694117647058824 0.764705882352941 1" />
      </material>
    </visual>
    <collision>
      <origin
        xyz="0 0 0"
        rpy="0 0 0" />
      <geometry>
        <mesh
          filename="package://SCARA/meshes/l2.STL" />
      </geometry>
    </collision>
  </link>
  <joint
    name="j2"
    type="continuous">
    <origin
      xyz="0.225 -0.001327 0.0482"
      rpy="0 0 -0.011151" />
    <parent
      link="l1" />
    <child
      link="l2" />
    <axis
      xyz="0 0 1" />
    <limit
      lower="-3"
      upper="3"
      effort="50"
      velocity="2" />
    <dynamics
      damping="0.01"
      friction="0.1" />
    <safety_controller
      soft_upper_limit="3"
      soft_lower_limit="-3"
      k_position="80"
      k_velocity="0.1" />
  </joint>
  <link
    name="l3">
    <inertial>
      <origin
        xyz="0.000723929217276431 -0.0014484451493568 0.0589095639572079"
        rpy="0 0 0" />
      <mass
        value="0.118783242273913" />
      <inertia
        ixx="0.00138513463723205"
        ixy="7.80537835970777E-12"
        ixz="5.6031245688995E-07"
        iyy="0.00138517582551882"
        iyz="-2.36712138308125E-09"
        izz="8.02190061536944E-06" />
    </inertial>
    <visual>
      <origin
        xyz="0 0 0"
        rpy="0 0 0" />
      <geometry>
        <mesh
          filename="package://SCARA/meshes/l3.STL" />
      </geometry>
      <material
        name="">
        <color
          rgba="0.5 0.6 0.7 1" />
      </material>
    </visual>
    <collision>
      <origin
        xyz="0 0 0"
        rpy="0 0 0" />
      <geometry>
        <mesh
          filename="package://SCARA/meshes/l3.STL" />
      </geometry>
    </collision>
  </link>
  <joint
    name="j3"
    type="prismatic">
    <origin
      xyz="0.175 -0.00018422 -0.0091"
      rpy="0 0 2.6487" />
    <parent
      link="l2" />
    <child
      link="l3" />
    <axis
      xyz="0 0 1" />
    <limit
      lower="-0.2"
      upper="0.12"
      effort="10"
      velocity="0.1" />
    <dynamics
      damping="0.01"
      friction="0.1" />
    <safety_controller
      soft_upper_limit="1"
      soft_lower_limit="-0.5"
      k_position="20"
      k_velocity="0.01" />
  </joint>
  <link
    name="l4">
    <inertial>
      <origin
        xyz="-1.6923210590325E-05 0.000253238906820726 0.00499298854231604"
        rpy="0 0 0" />
      <mass
        value="0.00589585954631894" />
      <inertia
        ixx="5.13352329553493E-07"
        ixy="-2.52673861718143E-11"
        ixz="3.99807072173318E-10"
        iyy="5.30497593820238E-07"
        iyz="-1.04685342052486E-11"
        izz="9.45751531567891E-07" />
    </inertial>
    <visual>
      <origin
        xyz="0 0 0"
        rpy="0 0 0" />
      <geometry>
        <mesh
          filename="package://SCARA/meshes/l4.STL" />
      </geometry>
      <material
        name="">
        <color
          rgba="0 0 0 1" />
      </material>
    </visual>
    <collision>
      <origin
        xyz="0 0 0"
        rpy="0 0 0" />
      <geometry>
        <mesh
          filename="package://SCARA/meshes/l4.STL" />
      </geometry>
    </collision>
  </link>
  <joint
    name="j4"
    type="continuous">
    <origin
      xyz="0.0007245 -0.0013262 -0.11879"
      rpy="0 0 -2.7383" />
    <parent
      link="l3" />
    <child
      link="l4" />
    <axis
      xyz="0 0 1" />
    <limit
      lower="-4"
      upper="4"
      effort="100"
      velocity="0.2" />
    <dynamics
      damping="0.01"
      friction="0.2" />
    <safety_controller
      soft_upper_limit="4"
      soft_lower_limit="-4"
      k_position="20"
      k_velocity="0.01" />
  </joint>
</robot>